<?xml version="1.0" ?>
<robot xmlns:xacro="http://ros.org/wiki/xacro">

  <!--
  <xacro:property name="pi" value="3.141592654" />
  -->

  <!-- right leg -->
  <xacro:macro name="robotis_op3_r_leg" params="parent">

  <!-- right hip yaw joint -->
  <joint name="r_hip_yaw" type="revolute">
    <parent link="${parent}"/>
    <child link="r_hip_yaw_link"/>
    <origin xyz="0.0 -0.035 0.0" rpy="0 0 0" />
    <axis xyz="0 0 -1" />
    <limit effort="1000" velocity="100" lower="${-pi*0.9}" upper="${pi*0.9}" />
    <dynamics damping="0.1" friction="0.0" />
  </joint>
  <xacro:insert_transmission name="r_hip_yaw" />

  <!-- right hip yaw link -->
  <link name="r_hip_yaw_link">
    <visual>
      <xacro:insert_mesh_r_hip_yaw_link />
    </visual>
    <collision>
      <xacro:insert_mesh_r_hip_yaw_link />
    </collision>
    <inertial>
      <xacro:insert_inertia_r_hip_yaw_link />
    </inertial>
  </link>

  <!-- right hip roll joint -->
  <joint name="r_hip_roll" type="revolute">
    <parent link="r_hip_yaw_link"/>
    <child link="r_hip_roll_link"/>
    <origin xyz="-0.024 0.0 -0.0285" rpy="0 0 0" />
    <axis xyz="-1 0 0" />
    <limit effort="1000" velocity="100" lower="${-pi*0.9}" upper="${pi*0.9}" />
    <dynamics damping="0.1" friction="0.0" />
  </joint>
  <xacro:insert_transmission name="r_hip_roll" />

  <!-- right hip roll link -->
  <link name="r_hip_roll_link">
    <visual>
      <xacro:insert_mesh_r_hip_roll_link />
    </visual>
    <collision>
      <xacro:insert_mesh_r_hip_roll_link />
    </collision>
    <inertial>
      <xacro:insert_inertia_r_hip_roll_link />
    </inertial>
  </link>

  <!-- right hip pitch joint -->
  <joint name="r_hip_pitch" type="revolute">
    <parent link="r_hip_roll_link"/>
    <child link="r_hip_pitch_link"/>
    <origin xyz="0.0241 -0.019 0.0" rpy="0 0 0" />
    <axis xyz="0 -1 0" />
    <limit effort="1000" velocity="100" lower="${-pi*0.9}" upper="${pi*0.9}" />
    <dynamics damping="0.1" friction="0.0" />
  </joint>
  <xacro:insert_transmission name="r_hip_pitch" />

  <!-- right hip pitch link -->
  <link name="r_hip_pitch_link">
    <visual>
      <xacro:insert_mesh_r_hip_pitch_link />
    </visual>
    <collision>
      <xacro:insert_mesh_r_hip_pitch_link />
    </collision>
    <inertial>
      <xacro:insert_inertia_r_hip_pitch_link />
    </inertial>
  </link>

  <!-- right knee joint -->
  <joint name="r_knee" type="revolute">
    <parent link="r_hip_pitch_link"/>
    <child link="r_knee_link"/>
    <origin xyz="0.0 0.0 -0.11015" rpy="0 0 0" />
    <axis xyz="0 -1 0" />
    <limit effort="1000" velocity="100" lower="${-pi*0.9}" upper="${pi*0.9}" />
    <dynamics damping="0.1" friction="0.0" />
  </joint>
  <xacro:insert_transmission name="r_knee" />

  <!-- right hip pitch link -->
  <link name="r_knee_link">
    <visual>
      <xacro:insert_mesh_r_knee_link />
    </visual>
    <collision>
      <xacro:insert_mesh_r_knee_link />
    </collision>
    <inertial>
      <xacro:insert_inertia_r_knee_link />
    </inertial>
  </link>

  <!-- right ankle pitch link -->
  <joint name="r_ank_pitch" type="revolute">
    <parent link="r_knee_link"/>
    <child link="r_ank_pitch_link"/>
    <origin xyz="0 0 -0.110" rpy="0 0 0" />
    <axis xyz="0 1 0" />
    <limit effort="1000" velocity="100" lower="${-pi*0.9}" upper="${pi*0.9}" />
    <dynamics damping="0.1" friction="0.0" />
  </joint>
  <xacro:insert_transmission name="r_ank_pitch" />

  <!-- right hip pitch link -->
  <link name="r_ank_pitch_link">
    <visual>
      <xacro:insert_mesh_r_ank_pitch_link />
    </visual>
    <collision>
      <xacro:insert_mesh_r_ank_pitch_link />
    </collision>
    <inertial>
      <xacro:insert_inertia_r_ank_pitch_link />
    </inertial>
  </link>

  <!-- right ankle roll link -->
  <joint name="r_ank_roll" type="revolute">
    <parent link="r_ank_pitch_link"/>
    <child link="r_ank_roll_link"/>
    <origin xyz="-0.0241 0.019 0" rpy="0 0 0" />
    <axis xyz="1 0 0" />
    <limit effort="1000" velocity="100" lower="${-pi*0.9}" upper="${pi*0.9}" />
    <dynamics damping="0.1" friction="0.0" />
  </joint>
  <xacro:insert_transmission name="r_ank_roll" />

  <!-- right hip roll link -->
  <link name="r_ank_roll_link">
    <visual>
      <xacro:insert_mesh_r_ank_roll_link />
    </visual>
    <collision>
      <xacro:insert_mesh_r_ank_roll_link />
    </collision>
    <inertial>
      <xacro:insert_inertia_r_ank_roll_link />
    </inertial>
  </link>

  </xacro:macro>

</robot>
