<?xml version="1.0" ?>
<robot name="marm">
    <!-- /////////////////////////////////////    COLOR    ///////////////////////////////////////////// -->
    <material name="Black">
        <color rgba="0 0 0 1" />
    </material>
    <material name="White">
        <color rgba="1 1 1 1" />
    </material>
    <material name="Blue">
        <color rgba="0 0 1 1" />
    </material>
    <material name="Red">
        <color rgba="1 0 0 1" />
    </material>

    <joint name="bottom_joint" type="fixed">
        <origin xyz="0 0 0" rpy="0 0 0" />
        <parent link="base_link"/>
        <child link="bottom_link"/>
    </joint>
    <link name="bottom_link">
        <visual>
              <origin xyz=" 0 0 -0.01"  rpy="0 0 0"/>
                  <geometry>
                       <box size="0.2 0.2 0.02" />
                  </geometry>
              <material name="Brown" />
        </visual>
        <collision>
            <origin xyz=" 0 0 -0.01"  rpy="0 0 0"/>
            <geometry>
                <box size="0.2 0.2 0.02" />
            </geometry>
        </collision>
        <inertial>
            <mass value="500" />
            <inertia ixx="1.0" ixy="0.0" ixz="0.0" iyy="0.5" iyz="0.0" izz="1.0" />
        </inertial>
    </link>

    <!-- /////////////////////////////////////    BASE    ///////////////////////////////////////////// -->
    <link name="base_link">
        <visual>
            <origin rpy="0 0 0" xyz="0 0 0" />
            <geometry>
                <cylinder length="0.04" radius="0.05" />
            </geometry>
            <material name="White" />
        </visual>
        <collision>
            <origin rpy="0 0 0" xyz="0 0 0" />
            <geometry>
                <cylinder length="0.04" radius="0.05" />
            </geometry>
        </collision>
        
<inertial>
            <mass value="0.1" />
            <inertia ixx="0.03" iyy="0.03" izz="0.03" ixy="0.0" ixz="0.0" iyz="0.0" />
        </inertial>

    </link>
    <!-- /////////////////////////////////////   LINK1  ////////////////////////////////////////////// -->
    <link name="link1">
        <visual>
            <origin rpy="0 1.5707 0" xyz="-0.05 0 0" />
            <geometry>
                <cylinder length="0.1" radius="0.03" />
            </geometry>
            <material name="Blue" />
        </visual>
        <collision>
            <origin rpy="0 1.5707 0" xyz="-0.05 0 0" />
            <geometry>
                <cylinder length="0.1" radius="0.03" />
            </geometry>
        </collision>
        
<inertial>
            <mass value="0.1" />
            <inertia ixx="0.03" iyy="0.03" izz="0.03" ixy="0.0" ixz="0.0" iyz="0.0" />
        </inertial>

    </link>
    <joint name="joint1" type="revolute">
        <parent link="base_link" />
        <child link="link1" />
        <origin rpy="0 1.5707 0" xyz="0 0 0.02" />
        <axis xyz="-1 0 0" />
        <limit effort="300" lower="-3.14159" upper="3.14159" velocity="1" />
    </joint>
    <!-- ///////////////////////////////////////   LINK2  ////////////////////////////////////////////// -->
    <link name="link2">
        <visual>
            <origin rpy="0 0 0" xyz="0 0 0.07" />
            <geometry>
                <cylinder length="0.14" radius="0.03" />
            </geometry>
            <material name="White" />
        </visual>
        <collision>
            <origin rpy="0 0 0" xyz="0 0 0.07" />
            <geometry>
                <cylinder length="0.14" radius="0.03" />
            </geometry>
        </collision>
        
<inertial>
            <mass value="0.1" />
            <inertia ixx="0.03" iyy="0.03" izz="0.03" ixy="0.0" ixz="0.0" iyz="0.0" />
        </inertial>

    </link>
    <joint name="joint2" type="revolute">
        <parent link="link1" />
        <child link="link2" />
        <origin rpy="-1.5707 0 1.5707" xyz="-0.1 0 0.0" />
        <axis xyz="1 0 0" />
        <limit effort="300" lower="-3.14159" upper="3.14159" velocity="1" />
    </joint>
    <!-- /////////////////////////////////   LINK3  ///////////////////////////////////////////////////// -->
    <link name="link3">
        <visual>
            <origin rpy="0 0 0" xyz="0 0 -0.075" />
            <geometry>
                <cylinder length="0.15" radius="0.03" />
            </geometry>
            <material name="Blue" />
        </visual>
        <collision>
            <origin rpy="0 0 0" xyz="0 0 -0.075" />
            <geometry>
                <cylinder length="0.15" radius="0.03" />
            </geometry>
        </collision>
        
<inertial>
            <mass value="0.1" />
            <inertia ixx="0.03" iyy="0.03" izz="0.03" ixy="0.0" ixz="0.0" iyz="0.0" />
        </inertial>

    </link>
    <joint name="joint3" type="revolute">
        <parent link="link2" />
        <child link="link3" />
        <origin rpy="0 3.14159 0" xyz="0 0 0.14" />
        <axis xyz="-1 0 0" />
        <limit effort="300" lower="-3.14159" upper="3.14159" velocity="1" />
    </joint>
    <!-- ///////////////////////////////////   LINK4  //////////////////////////////////////////////// -->
    <link name="link4">
        <visual>
            <origin rpy="0 1.5707 0" xyz="0.03 0 0" />
            <geometry>
                <cylinder length="0.06" radius="0.025" />
            </geometry>
            <material name="Black" />
        </visual>
        <collision>
            <origin rpy="0 1.5707 0" xyz="0.03 0 0" />
            <geometry>
                <cylinder length="0.06" radius="0.025" />
            </geometry>
        </collision>
        
<inertial>
            <mass value="0.1" />
            <inertia ixx="0.03" iyy="0.03" izz="0.03" ixy="0.0" ixz="0.0" iyz="0.0" />
        </inertial>

    </link>
    <joint name="joint4" type="revolute">
        <parent link="link3" />
        <child link="link4" />
        <origin rpy="0 1.5707 3.14159" xyz="0.0 0.0 -0.15" />
        <axis xyz="1 0 0" />
        <limit effort="300" lower="-3.14159" upper="3.14159" velocity="1" />
    </joint>
    <!-- //////////////////////////////////   LINK5  ///////////////////////////////////////////////// -->
    <link name="link5">
        <visual>
            <origin rpy="0 0 0" xyz="0 0 0.03" />
            <geometry>
                <cylinder length="0.06" radius="0.03" />
            </geometry>
            <material name="White" />
        </visual>
        <collision>
            <origin rpy="0 0 0" xyz="0 0 0.03" />
            <geometry>
                <cylinder length="0.06" radius="0.03" />
            </geometry>
        </collision>
        
<inertial>
            <mass value="0.1" />
            <inertia ixx="0.03" iyy="0.03" izz="0.03" ixy="0.0" ixz="0.0" iyz="0.0" />
        </inertial>

    </link>
    <joint name="joint5" type="revolute">
        <parent link="link4" />
        <child link="link5" />
        <origin rpy="0 1.5707 0" xyz="0.06 0.0 0.0" />
        <axis xyz="1 0 0" />
        <limit effort="300" lower="-3.14159" upper="3.14159" velocity="1" />
    </joint>
    <!-- ////////////////////////////////   LINK6  ///////////////////////////////////////////////// -->
    <link name="link6">
        <visual>
            <origin rpy="0 1.5707 0" xyz="0.01 0 0 " />
            <geometry>
                <cylinder length="0.02" radius="0.04" />
            </geometry>
            <material name="Blue" />
        </visual>
        <collision>
            <origin rpy="0 1.5707 0" xyz="0.01 0 0 " />
            <geometry>
                <cylinder length="0.02" radius="0.04" />
            </geometry>
        </collision>
        
<inertial>
            <mass value="0.1" />
            <inertia ixx="0.03" iyy="0.03" izz="0.03" ixy="0.0" ixz="0.0" iyz="0.0" />
        </inertial>

    </link>
    <joint name="joint6" type="revolute">
        <parent link="link5" />
        <child link="link6" />
        <origin rpy="4.712385 -1.5707 0" xyz="0 0 0.06" />
        <axis xyz="1 0 0" />
        <limit effort="300" lower="-6.28318" upper="6.28318" velocity="1" />
    </joint>
    <!-- //////////////////////////////////////   GRIPPER   ////////////////////////////////////////////// -->
    <link name="gripper_finger_link1">
        <visual>
            <origin rpy="0 1.5707 0" xyz="0.03 0 0" />
            <geometry>
                <box size="0.03 0.01 0.06" />
            </geometry>
            <material name="White" />
        </visual>
        <collision>
            <origin rpy="0 1.5707 0" xyz="0.03 0 0" />
            <geometry>
                <box size="0.03 0.01 0.06" />
            </geometry>
        </collision>
        
<inertial>
            <mass value="0.1" />
            <inertia ixx="0.03" iyy="0.03" izz="0.03" ixy="0.0" ixz="0.0" iyz="0.0" />
        </inertial>

    </link>
    <link name="gripper_finger_link2">
        <visual>
            <origin rpy="0 1.5707 0" xyz="0.03 0 0" />
            <geometry>
                <box size="0.03 0.01 0.06" />
            </geometry>
            <material name="White" />
        </visual>
        <collision>
            <origin rpy="0 1.5707 0" xyz="0.03 0 0" />
            <geometry>
                <box size="0.03 0.01 0.06" />
            </geometry>
        </collision>
        
<inertial>
            <mass value="0.1" />
            <inertia ixx="0.03" iyy="0.03" izz="0.03" ixy="0.0" ixz="0.0" iyz="0.0" />
        </inertial>

    </link>
    <joint name="finger_joint1" type="prismatic">
        <parent link="link6" />
        <child link="gripper_finger_link1" />
        <origin rpy="0 0 0" xyz="0.02 -0.03 0" />
        <axis xyz="0 1 0" />
        <limit effort="100" lower="0" upper="0.03" velocity="0.02" />
    </joint>
    <joint name="finger_joint2" type="prismatic">
        <parent link="link6" />
        <child link="gripper_finger_link2" />
        <origin rpy="0 0 0" xyz="0.02 0.03 0" />
        <axis xyz="0 -1 0" />
        <limit effort="100" lower="0" upper="0.03" velocity="0.02" />
    </joint>

    <!-- //////////////////////////////////////   GRASPING FRAME   ////////////////////////////////////////////// -->
    <link name="grasping_frame" />
    <joint name="grasping_frame_joint" type="fixed">
        <parent link="link6" />
        <child link="grasping_frame" />
        <origin rpy="0 0 0" xyz="0.06 0 0" />
    </joint>

    <joint name="kinect_joint" type="fixed">
        <origin xyz="0.1 0 0.8" rpy="0 1.308996939 0" />
        <parent link="base_link"/>
        <child link="camera_link"/>
    </joint>

    <link name="camera_link">
            <origin xyz="0 0 0" rpy="0 0 0"/>
            <visual>
                <origin xyz="0 0 0" rpy="0 0 1.5708"/>
                <geometry>
                    <mesh filename="package://marm_description/meshes/kinect.dae" />
                </geometry>
            </visual>
            <collision>
                <geometry>
                    <box size="0.07 0.3 0.09"/>
                </geometry>
            </collision>
        </link>

        <joint name="camera_optical_joint" type="fixed">
            <origin xyz="0 0 0" rpy="-1.5708 0 -1.5708"/>
            <parent link="camera_link"/>
            <child link="camera_frame_optical"/>
        </joint>

        <link name="camera_frame_optical"/>

        <gazebo reference="camera_link">
            <sensor type="depth" name="camera">
                <always_on>true</always_on>
                <update_rate>20.0</update_rate>
                <camera>
                    <horizontal_fov>1.047</horizontal_fov>
                    <image>
                        <format>R8G8B8</format>
                        <width>640</width>
                        <height>480</height>
                    </image>
                    <clip>
                        <near>0.05</near>
                        <far>8.0</far>
                    </clip>
                </camera>
                <plugin name="kinect_camera_controller" filename="libgazebo_ros_openni_kinect.so">
                    <cameraName>camera</cameraName>
                    <alwaysOn>true</alwaysOn>
                    <updateRate>10</updateRate>
                    <imageTopicName>rgb/image_raw</imageTopicName>
                    <depthImageTopicName>depth/image_raw</depthImageTopicName>
                    <pointCloudTopicName>depth/points</pointCloudTopicName>
                    <cameraInfoTopicName>rgb/camera_info</cameraInfoTopicName>
                    <depthImageCameraInfoTopicName>depth/camera_info</depthImageCameraInfoTopicName>
                    <frameName>camera_frame_optical</frameName>
                    <baseline>0.1</baseline>
                    <distortion_k1>0.0</distortion_k1>
                    <distortion_k2>0.0</distortion_k2>
                    <distortion_k3>0.0</distortion_k3>
                    <distortion_t1>0.0</distortion_t1>
                    <distortion_t2>0.0</distortion_t2>
                    <pointCloudCutoff>0.4</pointCloudCutoff>
                </plugin>
            </sensor>
        </gazebo>

    
<transmission name="trans_joint1">
        <type>transmission_interface/SimpleTransmission</type>
        <joint name="joint1">
            <hardwareInterface>hardware_interface/PositionJointInterface</hardwareInterface>
        </joint>
        <actuator name="joint1_motor">
            <hardwareInterface>hardware_interface/PositionJointInterface</hardwareInterface>
            <mechanicalReduction>1</mechanicalReduction>
        </actuator>
    </transmission>
    <transmission name="trans_joint2">
        <type>transmission_interface/SimpleTransmission</type>
        <joint name="joint2">
            <hardwareInterface>hardware_interface/PositionJointInterface</hardwareInterface>
        </joint>
        <actuator name="joint2_motor">
            <hardwareInterface>hardware_interface/PositionJointInterface</hardwareInterface>
            <mechanicalReduction>1</mechanicalReduction>
        </actuator>
    </transmission>
    <transmission name="trans_joint3">
        <type>transmission_interface/SimpleTransmission</type>
        <joint name="joint3">
            <hardwareInterface>hardware_interface/PositionJointInterface</hardwareInterface>
        </joint>
        <actuator name="joint3_motor">
            <hardwareInterface>hardware_interface/PositionJointInterface</hardwareInterface>
            <mechanicalReduction>1</mechanicalReduction>
        </actuator>
    </transmission>
    <transmission name="trans_joint4">
        <type>transmission_interface/SimpleTransmission</type>
        <joint name="joint4">
            <hardwareInterface>hardware_interface/PositionJointInterface</hardwareInterface>
        </joint>
        <actuator name="joint4_motor">
            <hardwareInterface>hardware_interface/PositionJointInterface</hardwareInterface>
            <mechanicalReduction>1</mechanicalReduction>
        </actuator>
    </transmission>
    <transmission name="trans_joint5">
        <type>transmission_interface/SimpleTransmission</type>
        <joint name="joint5">
            <hardwareInterface>hardware_interface/PositionJointInterface</hardwareInterface>
        </joint>
        <actuator name="joint5_motor">
            <hardwareInterface>hardware_interface/PositionJointInterface</hardwareInterface>
            <mechanicalReduction>1</mechanicalReduction>
        </actuator>
    </transmission>
    <transmission name="trans_joint6">
        <type>transmission_interface/SimpleTransmission</type>
        <joint name="joint6">
            <hardwareInterface>hardware_interface/PositionJointInterface</hardwareInterface>
        </joint>
        <actuator name="joint6_motor">
            <hardwareInterface>hardware_interface/PositionJointInterface</hardwareInterface>
            <mechanicalReduction>1</mechanicalReduction>
        </actuator>
    </transmission>
    <transmission name="trans_finger_joint1">
        <type>transmission_interface/SimpleTransmission</type>
        <joint name="finger_joint1">
            <hardwareInterface>hardware_interface/PositionJointInterface</hardwareInterface>
        </joint>
        <actuator name="finger_joint1_motor">
            <hardwareInterface>hardware_interface/PositionJointInterface</hardwareInterface>
            <mechanicalReduction>1</mechanicalReduction>
        </actuator>
    </transmission>
    <transmission name="trans_finger_joint2">
        <type>transmission_interface/SimpleTransmission</type>
        <joint name="finger_joint2">
            <hardwareInterface>hardware_interface/PositionJointInterface</hardwareInterface>
        </joint>
        <actuator name="finger_joint2_motor">
            <hardwareInterface>hardware_interface/PositionJointInterface</hardwareInterface>
            <mechanicalReduction>1</mechanicalReduction>
        </actuator>
    </transmission>
    <gazebo>
        <plugin name="gazebo_ros_control" filename="libgazebo_ros_control.so">
            <robotNamespace>/</robotNamespace>
        </plugin>
    </gazebo>
</robot>
