<?xml version="1.0"?>

<robot name="arm_hardware" xmlns:xacro="http://ros.org/wiki/xacro">

  <xacro:property name="PI" value="3.14159"/>
  <xacro:property name="DYNAMIXEL_MESH_SCALE" value="0.001"/>
  
  <xacro:property name="F2_WIDTH" value="0.0480"/>
  <xacro:property name="F2_HEIGHT" value="0.0380"/>
  <xacro:property name="F2_DEPTH" value="0.0245"/>
  
  <xacro:property name="F3_WIDTH" value="0.038"/>
  <xacro:property name="F3_HEIGHT" value="0.009"/>
  <xacro:property name="F3_DEPTH" value="0.025"/>
    
  <xacro:property name="F4_WIDTH" value="0.0480"/>
  <xacro:property name="F4_HEIGHT" value="0.0625"/>
  <xacro:property name="F4_DEPTH" value="0.0245"/>
  
  <xacro:property name="F9_DEPTH" value="0.025"/>
 
  <xacro:property name="F10_HEIGHT" value="0.004"/>
  <xacro:property name="F10_LENGTH" value="0.038"/>

  <xacro:property name="AX12_HEIGHT" value="0.0385"/>
  <xacro:property name="AX12_WIDTH" value="0.035"/>
  <xacro:property name="AX12_DEPTH" value="0.049"/>
    
  <xacro:property name="ARM_MESH_EXT" value="stl"/>

  <xacro:macro name="bioloid_F10_fixed" params="parent name color *origin">
    <joint name="${name}_joint" type="fixed">
      <xacro:insert_block name="origin" />
      <parent link="${parent}_link"/>
      <child link="${name}_link" />
    </joint>

    <link name="${name}_link">
      <inertial>
        <mass value="0.00001" />
        <origin xyz="0 0 0" />
        <inertia ixx="1.0" ixy="0.0" ixz="0.0"
          iyy="1.0" iyz="0.0"
          izz="1.0" />
      </inertial>

      <visual>
        <origin xyz=" 0 0 0 " rpy="0 0 0" />
        <geometry>
          <mesh filename="package://probot_description/meshes/gripper/F10.stl" scale="${DYNAMIXEL_MESH_SCALE} ${DYNAMIXEL_MESH_SCALE} ${DYNAMIXEL_MESH_SCALE}"/>
        </geometry>
        <material name="${color}"/>
      </visual>

      <collision>
        <origin xyz="0.0 0.0 0.0" rpy="0 0 0" />
        <geometry>
          <box size="0.025 0.038 0.004"/>
        </geometry>
      </collision>
    </link>
  </xacro:macro>
  
  <xacro:macro name="bioloid_F10_revolute" params="parent name color llimit ulimit vlimit *origin *axis">
    <joint name="${name}_joint" type="revolute">
      <xacro:insert_block name="origin" />
      <xacro:insert_block name="axis" />
      <limit effort="1.0" velocity="${vlimit}" lower="${llimit}" upper="${ulimit}" />
      <parent link="${parent}_link"/>
      <child link="${name}_link" />
    </joint>

    <link name="${name}_link">
      <inertial>
        <mass value="0.00001" />
        <origin xyz="0 0 0" />
        <inertia ixx="1.0" ixy="0.0" ixz="0.0"
          iyy="1.0" iyz="0.0"
          izz="1.0" />
      </inertial>

      <visual>
        <origin xyz=" 0 0 0 " rpy="0 0 0" />
        <geometry>
          <mesh filename="package://probot_description/meshes/gripper/F10.stl" scale="${DYNAMIXEL_MESH_SCALE} ${DYNAMIXEL_MESH_SCALE} ${DYNAMIXEL_MESH_SCALE}"/>
        </geometry>
        <material name="${color}"/>
      </visual>

      <collision>
        <origin xyz="0.0 0.0 0.0" rpy="0 0 0" />
        <geometry>
          <box size="0.025 0.038 0.004"/>
        </geometry>
      </collision>
    </link>
  </xacro:macro>
  
  <xacro:macro name="bioloid_F2_fixed" params="parent name color *origin">
    <joint name="${name}_joint" type="fixed">
      <xacro:insert_block name="origin" />
      <parent link="${parent}_link"/>
      <child link="${name}_link" />
    </joint>

    <link name="${name}_link">
      <inertial>
        <mass value="0.00001" />
        <origin xyz="0 0 0" />
        <inertia ixx="1.0" ixy="0.0" ixz="0.0"
          iyy="1.0" iyz="0.0"
          izz="1.0" />
      </inertial>

      <visual>
        <origin xyz=" 0 0 0 " rpy="0 0 0" />
        <geometry>
          <mesh filename="package://probot_description/meshes/gripper/F2.stl" scale="${DYNAMIXEL_MESH_SCALE} ${DYNAMIXEL_MESH_SCALE} ${DYNAMIXEL_MESH_SCALE}"/>
        </geometry>
        <material name="${color}"/>
      </visual>

      <collision>
        <origin xyz="0.0 0.0 0.00775" rpy="0 0 0" />
        <geometry>
          <box size="0.025 0.0485 0.0375"/>
        </geometry>
      </collision>
    </link>
  </xacro:macro>

  <xacro:macro name="finger" params="parent name color *origin">
    <joint name="${name}_joint" type="fixed">
      <xacro:insert_block name="origin" />
      <parent link="${parent}_link"/>
      <child link="${name}_link" />
    </joint>

    <link name="${name}_link">
      <inertial>
        <mass value="0.00001" />
        <origin xyz="0 0 0" />
        <inertia ixx="1.0" ixy="0.0" ixz="0.0"
          iyy="1.0" iyz="0.0"
          izz="1.0" />
      </inertial>

      <visual>
        <origin xyz=" 0 0 0 " rpy="0 0 0" />
        <geometry>
          <mesh filename="package://probot_description/meshes/gripper/finger.stl" scale="${DYNAMIXEL_MESH_SCALE} ${DYNAMIXEL_MESH_SCALE} ${DYNAMIXEL_MESH_SCALE}"/>
        </geometry>
        <material name="${color}"/>
      </visual>

      <collision>
        <origin xyz="0.02645 0.0 -0.00655" rpy="0 0 0" />
        <geometry>
          <box size="0.0783 0.03801 0.0193"/>
        </geometry>
      </collision>
    </link>

    <!-- Friction (in simulation) -->
    <gazebo reference="${name}_link">
      <kp>10000000.0</kp>
      <kd>1.0</kd>
      <mu1>2000.0</mu1>
      <mu2>1000.0</mu2>
      <minDepth>0.001</minDepth>
    </gazebo>

    <!-- Damping (in simulation) -->
    <gazebo reference="${name}_link">
      <implicitSpringDamper>true</implicitSpringDamper>
    </gazebo>

    <!-- Color (in simulation) -->
    <gazebo reference="${name}_link">
      <material>Gazebo/Grey</material>
    </gazebo>

  </xacro:macro>

  <xacro:macro name="bioloid_F3_fixed" params="parent name color *origin">
    <joint name="${name}_joint" type="fixed">
      <xacro:insert_block name="origin" />
      <parent link="${parent}_link"/>
      <child link="${name}_link" />
    </joint>

    <link name="${name}_link">
      <inertial>
        <mass value="0.00001" />
        <origin xyz="0 0 0" />
        <inertia ixx="1.0" ixy="0.0" ixz="0.0"
          iyy="1.0" iyz="0.0"
          izz="1.0" />
      </inertial>

      <visual>
        <origin xyz=" 0 0 0 " rpy="0 0 0" />
        <geometry>
          <mesh filename="package://probot_description/meshes/gripper/F3.stl" scale="${DYNAMIXEL_MESH_SCALE} ${DYNAMIXEL_MESH_SCALE} ${DYNAMIXEL_MESH_SCALE}"/>
        </geometry>
        <material name="${color}"/>
      </visual>

      <collision>
        <origin xyz="0.0 0.0 -0.0045" rpy="0 0 0" />
        <geometry>
          <box size="0.025 0.038 0.009"/>
        </geometry>
      </collision>
    </link>
  </xacro:macro>
  
  <xacro:macro name="bioloid_F9_fixed" params="parent name color *origin">
    <joint name="${name}_joint" type="fixed">
      <xacro:insert_block name="origin" />
      <parent link="${parent}_link"/>
      <child link="${name}_link" />
    </joint>

    <link name="${name}_link">
      <inertial>
        <mass value="0.00001" />
        <origin xyz="0 0 0" />
        <inertia ixx="1.0" ixy="0.0" ixz="0.0"
          iyy="1.0" iyz="0.0"
          izz="1.0" />
      </inertial>

      <visual>
        <origin xyz=" 0 0 0 " rpy="0 0 0" />
        <geometry>
          <mesh filename="package://probot_description/meshes/gripper/F9.stl" scale="${DYNAMIXEL_MESH_SCALE} ${DYNAMIXEL_MESH_SCALE} ${DYNAMIXEL_MESH_SCALE}"/>
        </geometry>
        <material name="${color}"/>
      </visual>

      <collision>
        <origin xyz="0.0 0.0 -0.0045" rpy="0 0 0" />
        <geometry>
          <box size="0.025 0.030 0.025"/>
        </geometry>
      </collision>
    </link>
  </xacro:macro>
  
  <xacro:macro name="bioloid_F11_fixed" params="parent name color *origin">
    <joint name="${name}_joint" type="fixed">
      <xacro:insert_block name="origin" />
      <parent link="${parent}_link"/>
      <child link="${name}_link" />
    </joint>

    <link name="${name}_link">
      <inertial>
        <mass value="0.00001" />
        <origin xyz="0 0 0" />
        <inertia ixx="1.0" ixy="0.0" ixz="0.0"
          iyy="1.0" iyz="0.0"
          izz="1.0" />
      </inertial>

      <visual>
        <origin xyz=" 0 0 0 " rpy="0 0 0" />
        <geometry>
          <mesh filename="package://probot_description/meshes/gripper/F11.stl" scale="${DYNAMIXEL_MESH_SCALE} ${DYNAMIXEL_MESH_SCALE} ${DYNAMIXEL_MESH_SCALE}"/>
        </geometry>
        <material name="${color}"/>
      </visual>

      <collision>
        <origin xyz="0 0.028 0" rpy="0 0 0" />
        <geometry>
          <box size="0.030 0.056 0.032"/>
        </geometry>
      </collision>
    </link>
  </xacro:macro>

  <xacro:macro name="dynamixel_AX12_fixed" params="parent name *origin">
    <joint name="${name}_joint" type="fixed">
      <xacro:insert_block name="origin" />
      <parent link="${parent}"/>
      <child link="${name}_link" />
    </joint>

    <link name="${name}_link">
      <inertial>
        <mass value="0.00001" />
        <origin xyz="0 0 0" />
        <inertia ixx="1.0" ixy="0.0" ixz="0.0"
          iyy="1.0" iyz="0.0"
          izz="1.0" />
      </inertial>

      <visual>
        <origin xyz=" 0 0 0 " rpy="0 0 0" />
        <geometry>
          <mesh filename="package://probot_description/meshes/gripper/ax12.${ARM_MESH_EXT}" scale="${DYNAMIXEL_MESH_SCALE} ${DYNAMIXEL_MESH_SCALE} ${DYNAMIXEL_MESH_SCALE}"/>
        </geometry>
        <material name="Black"/>
      </visual>

      <collision>
        <origin xyz="0.0 0.0 -0.01241" rpy="0 0 0" />
        <geometry>
          <box size="0.025 0.038 0.04762"/>
        </geometry>
      </collision>
    </link>
  </xacro:macro>
  
  <xacro:macro name="dynamixel_AX12_revolute" params="parent name llimit ulimit vlimit *origin *axis">
    <joint name="${name}_joint" type="revolute">
      <xacro:insert_block name="origin" />
      <xacro:insert_block name="axis" />
      <limit effort="1.0" velocity="${vlimit}" lower="${llimit}" upper="${ulimit}" />
      <parent link="${parent}_link"/>
      <child link="${name}_link" />
    </joint>

    <link name="${name}_link">
      <inertial>
        <mass value="0.00001" />
        <origin xyz="0 0 0" />
        <inertia ixx="1.0" ixy="0.0" ixz="0.0"
          iyy="1.0" iyz="0.0"
          izz="1.0" />
      </inertial>

      <visual>
        <origin xyz=" 0 0 0 " rpy="0 0 0" />
        <geometry>
          <mesh filename="package://probot_description/meshes/gripper/ax12.${ARM_MESH_EXT}" scale="${DYNAMIXEL_MESH_SCALE} ${DYNAMIXEL_MESH_SCALE} ${DYNAMIXEL_MESH_SCALE}"/>
        </geometry>
         <material name="Black"/>
      </visual>

      <collision>
        <origin xyz="0.0 0.0 -0.01241" rpy="0 0 0" />
        <geometry>
          <box size="0.025 0.038 0.04762"/>
        </geometry>
      </collision>
    </link>
  </xacro:macro>
  
  <xacro:macro name="bioloid_F3_revolute" params="parent name color llimit ulimit vlimit *origin *axis">
    <joint name="${name}_joint" type="revolute">
      <xacro:insert_block name="origin" />
      <xacro:insert_block name="axis" />
      <limit effort="1.0" velocity="${vlimit}" lower="${llimit}" upper="${ulimit}" />
      <parent link="${parent}_link"/>
      <child link="${name}_link" />
    </joint>

    <link name="${name}_link">
      <inertial>
        <mass value="0.00001" />
        <origin xyz="0 0 0" />
        <inertia ixx="1.0" ixy="0.0" ixz="0.0"
          iyy="1.0" iyz="0.0"
          izz="1.0" />
      </inertial>

      <visual>
        <origin xyz=" 0 0 0 " rpy="0 0 0" />
        <geometry>
          <mesh filename="package://probot_description/meshes/gripper/F3.stl" scale="${DYNAMIXEL_MESH_SCALE} ${DYNAMIXEL_MESH_SCALE} ${DYNAMIXEL_MESH_SCALE}"/>
        </geometry>
        <material name="${color}"/>
      </visual>

      <collision>
        <origin xyz="0.0 0.0 -0.0045" rpy="0 0 0" />
        <geometry>
          <box size="0.025 0.038 0.009"/>
        </geometry>
      </collision>
    </link>
  </xacro:macro>

  <xacro:macro name="bioloid_F2_revolute" params="parent name color llimit ulimit vlimit *origin *axis">
    <joint name="${name}_joint" type="revolute">
      <xacro:insert_block name="origin" />
      <xacro:insert_block name="axis" />
      <limit effort="1.0" velocity="${vlimit}" lower="${llimit}" upper="${ulimit}" />
      <parent link="${parent}_link"/>
      <child link="${name}_link" />
    </joint>

    <link name="${name}_link">
      <inertial>
        <mass value="0.00001" />
        <origin xyz="0 0 0" />
        <inertia ixx="1.0" ixy="0.0" ixz="0.0"
          iyy="1.0" iyz="0.0"
          izz="1.0" />
      </inertial>

      <visual>
        <origin xyz=" 0 0 0 " rpy="0 0 0" />
        <geometry>
          <mesh filename="package://probot_description/meshes/gripper/F2.stl" scale="${DYNAMIXEL_MESH_SCALE} ${DYNAMIXEL_MESH_SCALE} ${DYNAMIXEL_MESH_SCALE}"/>
        </geometry>
        <material name="${color}"/>
      </visual>

      <collision>
        <origin xyz="0.0 0.0 0.00775" rpy="0 0 0" />
        <geometry>
          <box size="0.025 0.0485 0.0375"/>
        </geometry>
      </collision>
    </link>
  </xacro:macro>

  <xacro:macro name="bioloid_F4_revolute" params="parent name color llimit ulimit vlimit *origin *axis">
    <joint name="${name}_joint" type="revolute">
      <xacro:insert_block name="origin" />
      <xacro:insert_block name="axis" />
      <limit effort="1.0" velocity="${vlimit}" lower="${llimit}" upper="${ulimit}" />
      <parent link="${parent}_link"/>
      <child link="${name}_link" />
    </joint>

    <link name="${name}_link">
      <inertial>
        <mass value="0.00001" />
        <origin xyz="0 0 0" />
        <inertia ixx="1.0" ixy="0.0" ixz="0.0"
          iyy="1.0" iyz="0.0"
          izz="1.0" />
      </inertial>

      <visual>
        <origin xyz=" 0 0 0 " rpy="0 0 0" />
        <geometry>
          <mesh filename="package://probot_description/meshes/gripper/F4.stl" scale="${DYNAMIXEL_MESH_SCALE} ${DYNAMIXEL_MESH_SCALE} ${DYNAMIXEL_MESH_SCALE}"/>
        </geometry>
        <material name="${color}"/>
      </visual>

      <collision>
        <origin xyz="0.0 0.0 0.0215" rpy="0 0 0" />
        <geometry>
          <box size="0.028 0.0485 0.065"/>
        </geometry>
      </collision>
    </link>
  </xacro:macro>

</robot>
