<?xml version="1.0" ?>
<robot name="mbot">

<!-- /////////////////////////////////////    COLOR    ///////////////////////////////////////////// -->
    <material name="Black">
        <color rgba="0 0 0 1"/>
    </material>
    <material name="White">
        <color rgba="1 1 1 0.95"/>
    </material>
    <material name="Blue">
        <color rgba="0 0 1 1"/>
    </material>
    <material name="Yellow">
        <color rgba="1 0.4 0 1"/>
    </material>

<!-- /////////////////////////////////////    BASE    ///////////////////////////////////////////// -->
    <link name="base_link">
        <visual>
            <origin xyz=" 0 0 0" rpy="0 0 0" />
            <geometry>
                <cylinder length="0.16" radius="0.20"/>
            </geometry>
            <material name="Yellow"/>
        </visual>
    </link>

<!-- /////////////////////////////////////    WHEEL    ///////////////////////////////////////////// -->

    <link name="left_wheel_link">
        <visual>
            <origin xyz="0 0 0" rpy="1.5707 0 0" />
            <geometry>
                <cylinder radius="0.06" length = "0.025"/>
            </geometry>
            <material name="White"/>
        </visual>
    </link>

    <joint name="left_wheel_joint" type="continuous">
        <origin xyz="0 0.19 -0.05" rpy="0 0 0"/>
        <parent link="base_link"/>
        <child link="left_wheel_link"/>
        <axis xyz="0 1 0"/>
    </joint>

    <link name="right_wheel_link">
        <visual>
            <origin xyz="0 0 0" rpy="1.5707 0 0" />
            <geometry>
                <cylinder radius="0.06" length = "0.025"/>
            </geometry>
            <material name="White"/>
        </visual>
    </link>

    <joint name="right_wheel_joint" type="continuous">
        <origin xyz="0 -0.19 -0.05" rpy="0 0 0"/>
        <parent link="base_link"/>
        <child link="right_wheel_link"/>
        <axis xyz="0 1 0"/>
    </joint>

<!-- /////////////////////////////////////    CASTER    ///////////////////////////////////////////// -->
    <link name="front_caster_link">
        <visual>
            <origin xyz="0 0 0" rpy="0 0 0"/>
            <geometry>
                <sphere radius="0.015" />
            </geometry>
            <material name="Black"/>
        </visual>
    </link>

    <joint name="front_caster_joint" type="fixed">
        <origin xyz="0.18 0 -0.095" rpy="0 0 0"/>
        <parent link="base_link"/>
        <child link="front_caster_link"/>
    </joint>

    <link name="back_caster_link">
        <visual>
            <origin xyz="0 0 0" rpy="0 0 0"/>
            <geometry>
                <sphere radius="0.015" />
            </geometry>
            <material name="Black"/>
        </visual>
    </link>

    <joint name="back_caster_joint" type="fixed">
        <origin xyz="-0.18 0 -0.095" rpy="0 0 0"/>
        <parent link="base_link"/>
        <child link="back_caster_link"/>
    </joint>

<!-- /////////////////////////////////////    LASER    ///////////////////////////////////////////// -->
    <link name="laser_link">
		<visual>
			<origin xyz=" 0 0 0 " rpy="0 0 0" />
			<geometry>
				<cylinder length="0.05" radius="0.05"/>
			</geometry>
			<material name="Black"/>
		</visual>
    </link>

    <joint name="laser_joint" type="fixed">
        <origin xyz="0 0 0.105" rpy="0 0 0"/>
        <parent link="base_link"/>
        <child link="laser_link"/>
    </joint>

</robot>
